#VRML_SIM R2020b utf8
WorldInfo {
  info [
    "The user drives a Supervisor by the Keyboard which drives slaves robots by using an emitter device."
  ]
  title "Omniscience"
  coordinateSystem "NUE"
}
Viewpoint {
  orientation -0.012296901349470573 0.9387131030150339 0.3444800378034808 3.03945
  position 0.355825 2.19322 -2.66436
}
TexturedBackground {
}
TexturedBackgroundLight {
}
CircleArena {
}
WoodenBox {
  translation -0.06339 0.05 0.372612
  rotation 0 1 0 0.5
  size 0.1 0.1 0.1
}
WoodenBox {
  translation 0.449512 0.05 -0.488552
  rotation 0 1 0 4.96782
  name "wooden box(1)"
  size 0.1 0.1 0.1
}
WoodenBox {
  translation 0.5 0.05 0.35471
  rotation 0 1 0 5.36782
  name "wooden box(2)"
  size 0.1 0.1 0.1
}
WoodenBox {
  translation -0.3 0.05 -0.36
  rotation 0 1 0 5.36782
  name "wooden box(3)"
  size 0.1 0.1 0.1
}
WoodenBox {
  translation -0.645944 0.05 0.192254
  rotation 0 1 0 5.36782
  name "wooden box(4)"
  size 0.1 0.1 0.1
}
DEF ROBOT1 Robot {
  translation -0.34470183124613896 -0.00021921873911685125 0.06914759623356442
  rotation -0.10605867866215556 -0.9942838471903169 -0.012295848765336004 0.23908784712736247
  children [
    DEF MAIN_BODY Transform {
      translation 0 0.0415 0
      children [
        Shape {
          appearance PBRAppearance {
            baseColor 0.0820075 0.364731 0.8
            roughness 1
            metalness 0
          }
          geometry DEF BODY Cylinder {
            height 0.08
            radius 0.045
          }
        }
      ]
    }
    HingeJoint {
      jointParameters HingeJointParameters {
        position 3.0399797283233405
        axis -1 0 0
        anchor 0 0.025 0
      }
      device [
        RotationalMotor {
          name "left wheel motor"
        }
        PositionSensor {
          name "left wheel sensor"
        }
      ]
      endPoint DEF LEFT_WHEEL Solid {
        translation -0.045 0.025 0
        rotation 1 0 0 1.9446902716766596
        children [
          DEF WHEEL Transform {
            rotation 0 0 1 1.57
            children [
              Shape {
                appearance PBRAppearance {
                  baseColor 1 0 0
                  roughness 1
                  metalness 0
                }
                geometry Cylinder {
                  height 0.01
                  radius 0.025
                }
              }
            ]
          }
        ]
        name "left wheel"
        boundingObject DEF WHEEL Transform {
          rotation 0 0 1 1.57
          children [
            Shape {
              appearance PBRAppearance {
                baseColor 1 0 0
                roughness 1
                metalness 0
              }
              geometry Cylinder {
                height 0.01
                radius 0.025
              }
            }
          ]
        }
        physics DEF PHYSICS_WHEEL Physics {
          density -1
          mass 0.05
        }
        linearVelocity 0.029076724897377962 -5.2167642801492566e-05 -0.11993200911714069
        angularVelocity -4.797298319183302 -0.00021640073717878874 -1.1628904999574412
      }
    }
    HingeJoint {
      jointParameters HingeJointParameters {
        position 3.0399796558724095
        axis -1 0 0
        anchor 0 0.025 0
      }
      device [
        RotationalMotor {
          name "right wheel motor"
        }
        PositionSensor {
          name "right wheel sensor"
        }
      ]
      endPoint DEF RIGHT_WHEEL Solid {
        translation 0.04499999999999999 0.025 0
        rotation 1 0 0 1.5473703441275901
        children [
          DEF WHEEL Transform {
            rotation 0 0 1 1.57
            children [
              Shape {
                appearance PBRAppearance {
                  baseColor 1 0 0
                  roughness 1
                  metalness 0
                }
                geometry Cylinder {
                  height 0.01
                  radius 0.025
                }
              }
            ]
          }
        ]
        name "right wheel"
        boundingObject USE WHEEL
        physics DEF PHYSICS_WHEEL Physics {
          density -1
          mass 0.05
        }
        linearVelocity 0.029067731403327298 -4.8586233213327934e-05 -0.11993273039902741
        angularVelocity -4.797298490273475 -0.00021777114340457818 -1.1628894909512961
      }
    }
    DEF LEFT_EYE DistanceSensor {
      translation -0.02 0.063 -0.042
      rotation 0 1 0 2.07
      children [
        DEF INFRARED Transform {
          rotation 0 0 1 1.57
          children [
            Shape {
              appearance PBRAppearance {
                baseColor 0.975691 0.981481 0.0252992
                roughness 1
                metalness 0
              }
              geometry Cylinder {
                height 0.004
                radius 0.008
              }
            }
          ]
        }
      ]
      name "ds0"
      lookupTable [
        0 1024 0
        0.05 1024 0
        0.15 0 0
      ]
      numberOfRays 2
      aperture 1
    }
    DEF RIGHT_EYE DistanceSensor {
      translation 0.02 0.063 -0.042
      rotation 0 1 0 1.07
      children [
        DEF INFRARED Transform {
          rotation 0 0 1 1.57
          children [
            Shape {
              appearance PBRAppearance {
                baseColor 0.975691 0.981481 0.0252992
                roughness 1
                metalness 0
              }
              geometry Cylinder {
                height 0.004
                radius 0.008
              }
            }
          ]
        }
      ]
      name "ds1"
      lookupTable [
        0 1024 0
        0.05 1024 0
        0.15 0 0
      ]
      numberOfRays 2
      aperture 1
    }
    Receiver {
    }
    Camera {
      translation 0 0.045 -0.045
      children [
        Transform {
          rotation 1 0 0 1.57
          children [
            Shape {
              appearance PBRAppearance {
                baseColor 0.8 0.8 0.8
                roughness 1
                metalness 0
              }
              geometry Cylinder {
                height 0.01
                radius 0.007
              }
            }
          ]
        }
      ]
    }
  ]
  name "robot1"
  boundingObject DEF MYBOT_BOUNDING Transform {
    translation 0 0.0415 0
    children [
      DEF BODY Cylinder {
        height 0.08
        radius 0.045
      }
    ]
  }
  physics DEF MYBOT_PHYSICS Physics {
    density -1
    mass 0.5
  }
  controller "slave"
  linearVelocity 0.02883755320301156 -6.405007021356845e-05 -0.11890960671259673
  angularVelocity 0.06213169510458549 0.0003063859864986579 0.014369055205418856
}
DEF ROBOT2 Robot {
  translation 0.32424782365214405 -0.00022899522936600802 0.5757167528229281
  rotation -0.00032732796577559023 -0.9999986398268468 -0.0016165397796690814 2.6454862572528377
  children [
    DEF MAIN_BODY Transform {
      translation 0 0.0415 0
      children [
        Shape {
          appearance PBRAppearance {
            baseColor 0.0820075 0.364731 0.8
            roughness 1
            metalness 0
          }
          geometry DEF BODY Cylinder {
            height 0.08
            radius 0.045
          }
        }
      ]
    }
    HingeJoint {
      jointParameters HingeJointParameters {
        position 3.039936407407731
        axis -1 0 0
        anchor 0 0.025 0
      }
      device [
        RotationalMotor {
          name "left wheel motor"
        }
        PositionSensor {
          name "left wheel sensor"
        }
      ]
      endPoint DEF LEFT_WHEEL Solid {
        translation -0.04499999999999999 0.025 0
        rotation 1 0 0 1.9447335925922693
        children [
          DEF WHEEL Transform {
            rotation 0 0 1 1.57
            children [
              Shape {
                appearance PBRAppearance {
                  baseColor 1 0 0
                  roughness 1
                  metalness 0
                }
                geometry Cylinder {
                  height 0.01
                  radius 0.025
                }
              }
            ]
          }
        ]
        name "left wheel"
        boundingObject DEF WHEEL Transform {
          rotation 0 0 1 1.57
          children [
            Shape {
              appearance PBRAppearance {
                baseColor 1 0 0
                roughness 1
                metalness 0
              }
              geometry Cylinder {
                height 0.01
                radius 0.025
              }
            }
          ]
        }
        physics DEF PHYSICS_WHEEL Physics {
          density -1
          mass 0.05
        }
        linearVelocity 0.059077081323520624 -3.9296394726804456e-05 0.10912175209026406
        angularVelocity 4.364686176391948 0.0004099745078179899 -2.3633713564769523
      }
    }
    HingeJoint {
      jointParameters HingeJointParameters {
        position 3.0399363698499116
        axis -1 0 0
        anchor 0 0.025 0
      }
      device [
        RotationalMotor {
          name "right wheel motor"
        }
        PositionSensor {
          name "right wheel sensor"
        }
      ]
      endPoint DEF RIGHT_WHEEL Solid {
        translation 0.045 0.025 0
        rotation 1 0 0 1.5474136301500885
        children [
          DEF WHEEL Transform {
            rotation 0 0 1 1.57
            children [
              Shape {
                appearance PBRAppearance {
                  baseColor 1 0 0
                  roughness 1
                  metalness 0
                }
                geometry Cylinder {
                  height 0.01
                  radius 0.025
                }
              }
            ]
          }
        ]
        name "right wheel"
        boundingObject USE WHEEL
        physics DEF PHYSICS_WHEEL Physics {
          density -1
          mass 0.05
        }
        linearVelocity 0.05909149249496273 -3.645972631225916e-05 0.1091125107808582
        angularVelocity 4.364685617197824 0.00040837141797244863 -2.363372256466826
      }
    }
    DEF LEFT_EYE DistanceSensor {
      translation -0.02 0.063 -0.042
      rotation 0 1 0 2.07
      children [
        DEF INFRARED Transform {
          rotation 0 0 1 1.57
          children [
            Shape {
              appearance PBRAppearance {
                baseColor 0.975691 0.981481 0.0252992
                roughness 1
                metalness 0
              }
              geometry Cylinder {
                height 0.004
                radius 0.008
              }
            }
          ]
        }
      ]
      name "ds0"
      lookupTable [
        0 1024 0
        0.05 1024 0
        0.15 0 0
      ]
      numberOfRays 2
      aperture 1
    }
    DEF RIGHT_EYE DistanceSensor {
      translation 0.02 0.063 -0.042
      rotation 0 1 0 1.07
      children [
        DEF INFRARED Transform {
          rotation 0 0 1 1.57
          children [
            Shape {
              appearance PBRAppearance {
                baseColor 0.975691 0.981481 0.0252992
                roughness 1
                metalness 0
              }
              geometry Cylinder {
                height 0.004
                radius 0.008
              }
            }
          ]
        }
      ]
      name "ds1"
      lookupTable [
        0 1024 0
        0.05 1024 0
        0.15 0 0
      ]
      numberOfRays 2
      aperture 1
    }
    Receiver {
    }
    Camera {
      translation 0 0.045 -0.045
      children [
        Transform {
          rotation 1 0 0 1.57
          children [
            Shape {
              appearance PBRAppearance {
                baseColor 0.8 0.8 0.8
                roughness 1
                metalness 0
              }
              geometry Cylinder {
                height 0.01
                radius 0.007
              }
            }
          ]
        }
      ]
    }
  ]
  name "robot2"
  boundingObject DEF MYBOT_BOUNDING Transform {
    translation 0 0.0415 0
    children [
      DEF BODY Cylinder {
        height 0.08
        radius 0.045
      }
    ]
  }
  physics DEF MYBOT_PHYSICS Physics {
    density -1
    mass 0.5
  }
  controller "slave"
  linearVelocity 0.05882015509030107 -7.742616845359902e-05 0.10857797820078652
  angularVelocity -0.032738847811865326 -0.000525556137180261 0.016261572243327086
}
DEF ROBOT3 Robot {
  translation 0.10651579129614495 -0.00021961758516182012 0.05937343997331335
  rotation 0.004342596934774434 0.9999051968111144 -0.013066722695027634 2.5140010379653828
  children [
    DEF MAIN_BODY Transform {
      translation 0 0.0415 0
      children [
        Shape {
          appearance PBRAppearance {
            baseColor 0.0820075 0.364731 0.8
            roughness 1
            metalness 0
          }
          geometry DEF BODY Cylinder {
            height 0.08
            radius 0.045
          }
        }
      ]
    }
    HingeJoint {
      jointParameters HingeJointParameters {
        position 3.0399106709869086
        axis -1 0 0
        anchor 0 0.025 0
      }
      device [
        RotationalMotor {
          name "left wheel motor"
        }
        PositionSensor {
          name "left wheel sensor"
        }
      ]
      endPoint DEF LEFT_WHEEL Solid {
        translation -0.045 0.025 0
        rotation 1 0 0 1.9447593290130916
        children [
          DEF WHEEL Transform {
            rotation 0 0 1 1.57
            children [
              Shape {
                appearance PBRAppearance {
                  baseColor 1 0 0
                  roughness 1
                  metalness 0
                }
                geometry Cylinder {
                  height 0.01
                  radius 0.025
                }
              }
            ]
          }
        ]
        name "left wheel"
        boundingObject DEF WHEEL Transform {
          rotation 0 0 1 1.57
          children [
            Shape {
              appearance PBRAppearance {
                baseColor 1 0 0
                roughness 1
                metalness 0
              }
              geometry Cylinder {
                height 0.01
                radius 0.025
              }
            }
          ]
        }
        physics DEF PHYSICS_WHEEL Physics {
          density -1
          mass 0.05
        }
        linearVelocity -0.07019520422032399 -3.897634848527785e-05 0.09669650224637943
        angularVelocity 3.868061782905632 -0.00047395782755293585 2.807469462950565
      }
    }
    HingeJoint {
      jointParameters HingeJointParameters {
        position 3.039910633996697
        axis -1 0 0
        anchor 0 0.025 0
      }
      device [
        RotationalMotor {
          name "right wheel motor"
        }
        PositionSensor {
          name "right wheel sensor"
        }
      ]
      endPoint DEF RIGHT_WHEEL Solid {
        translation 0.045000000000000005 0.025 0
        rotation 1 0 0 1.547439366003303
        children [
          DEF WHEEL Transform {
            rotation 0 0 1 1.57
            children [
              Shape {
                appearance PBRAppearance {
                  baseColor 1 0 0
                  roughness 1
                  metalness 0
                }
                geometry Cylinder {
                  height 0.01
                  radius 0.025
                }
              }
            ]
          }
        ]
        name "right wheel"
        boundingObject USE WHEEL
        physics DEF PHYSICS_WHEEL Physics {
          density -1
          mass 0.05
        }
        linearVelocity -0.07017835943840077 -3.531775880446721e-05 0.09670668946991645
        angularVelocity 3.8680623514260235 -0.00047561082102650374 2.8074685402691677
      }
    }
    DEF LEFT_EYE DistanceSensor {
      translation -0.02 0.063 -0.042
      rotation 0 1 0 2.07
      children [
        DEF INFRARED Transform {
          rotation 0 0 1 1.57
          children [
            Shape {
              appearance PBRAppearance {
                baseColor 0.975691 0.981481 0.0252992
                roughness 1
                metalness 0
              }
              geometry Cylinder {
                height 0.004
                radius 0.008
              }
            }
          ]
        }
      ]
      name "ds0"
      lookupTable [
        0 1024 0
        0.05 1024 0
        0.15 0 0
      ]
      numberOfRays 2
      aperture 1
    }
    DEF RIGHT_EYE DistanceSensor {
      translation 0.02 0.063 -0.042
      rotation 0 1 0 1.07
      children [
        DEF INFRARED Transform {
          rotation 0 0 1 1.57
          children [
            Shape {
              appearance PBRAppearance {
                baseColor 0.975691 0.981481 0.0252992
                roughness 1
                metalness 0
              }
              geometry Cylinder {
                height 0.004
                radius 0.008
              }
            }
          ]
        }
      ]
      name "ds1"
      lookupTable [
        0 1024 0
        0.05 1024 0
        0.15 0 0
      ]
      numberOfRays 2
      aperture 1
    }
    Receiver {
    }
    Camera {
      translation 0 0.045 -0.045
      children [
        Transform {
          rotation 1 0 0 1.57
          children [
            Shape {
              appearance PBRAppearance {
                baseColor 0.8 0.8 0.8
                roughness 1
                metalness 0
              }
              geometry Cylinder {
                height 0.01
                radius 0.007
              }
            }
          ]
        }
      ]
    }
  ]
  name "robot3"
  boundingObject DEF MYBOT_BOUNDING Transform {
    translation 0 0.0415 0
    children [
      DEF BODY Cylinder {
        height 0.08
        radius 0.045
      }
    ]
  }
  physics DEF MYBOT_PHYSICS Physics {
    density -1
    mass 0.5
  }
  controller "slave"
  linearVelocity -0.0680749146716719 -0.00015364848571334773 0.09374392256525874
  angularVelocity -0.17929591397731245 0.0006510642835683744 -0.12832603965863565
}
Robot {
  children [
    Emitter {
    }
  ]
  name "Driver"
  controller "driver"
  supervisor TRUE
}
